2024-11-06 13:26:26,924 ERROR: Exception on /chat/2 [GET] [in C:\pycharm\Finall_Project\venv\lib\site-packages\flask\app.py:838]
Traceback (most recent call last):
  File "C:\pycharm\Finall_Project\venv\lib\site-packages\flask\app.py", line 1473, in wsgi_app
    response = self.full_dispatch_request()
  File "C:\pycharm\Finall_Project\venv\lib\site-packages\flask\app.py", line 882, in full_dispatch_request
    rv = self.handle_user_exception(e)
  File "C:\pycharm\Finall_Project\venv\lib\site-packages\flask\app.py", line 880, in full_dispatch_request
    rv = self.dispatch_request()
  File "C:\pycharm\Finall_Project\venv\lib\site-packages\flask\app.py", line 865, in dispatch_request
    return self.ensure_sync(self.view_functions[rule.endpoint])(**view_args)  # type: ignore[no-any-return]
  File "C:\pycharm\Finall_Project\venv\lib\site-packages\flask_login\utils.py", line 290, in decorated_view
    return current_app.ensure_sync(func)(*args, **kwargs)
  File "C:\pycharm\Finall_Project\app\routes.py", line 201, in chat
    return render_template('chat.html', chat=chat, messages=messages, other_user=other_user)
  File "C:\pycharm\Finall_Project\venv\lib\site-packages\flask\templating.py", line 150, in render_template
    return _render(app, template, context)
  File "C:\pycharm\Finall_Project\venv\lib\site-packages\flask\templating.py", line 131, in _render
    rv = template.render(context)
  File "C:\pycharm\Finall_Project\venv\lib\site-packages\jinja2\environment.py", line 1304, in render
    self.environment.handle_exception()
  File "C:\pycharm\Finall_Project\venv\lib\site-packages\jinja2\environment.py", line 939, in handle_exception
    raise rewrite_traceback_stack(source=source)
  File "C:\pycharm\Finall_Project\app\templates\chat.html", line 1, in top-level template code
    {% extends "base.html" %}
  File "C:\pycharm\Finall_Project\app\templates\base.html", line 33, in top-level template code
    {% block content %}{% endblock %}
  File "C:\pycharm\Finall_Project\app\templates\chat.html", line 10, in block 'content'
    <td><img src="{{ message.sender.avatar(36) }}"></td>
  File "C:\pycharm\Finall_Project\venv\lib\site-packages\jinja2\environment.py", line 487, in getattr
    return getattr(obj, attribute)
jinja2.exceptions.UndefinedError: 'app.models.Message object' has no attribute 'sender'
2024-11-06 13:31:31,351 INFO: Blog startup [in C:\pycharm\Finall_Project\app\__init__.py:31]
2024-11-06 13:33:20,209 INFO: Blog startup [in C:\pycharm\Finall_Project\app\__init__.py:31]
2024-11-06 13:41:44,605 INFO: Blog startup [in C:\pycharm\Finall_Project\app\__init__.py:31]
2024-11-06 13:41:49,297 ERROR: Exception on /chats [GET] [in C:\pycharm\Finall_Project\venv\lib\site-packages\flask\app.py:838]
Traceback (most recent call last):
  File "C:\pycharm\Finall_Project\venv\lib\site-packages\flask\app.py", line 1473, in wsgi_app
    response = self.full_dispatch_request()
  File "C:\pycharm\Finall_Project\venv\lib\site-packages\flask\app.py", line 882, in full_dispatch_request
    rv = self.handle_user_exception(e)
  File "C:\pycharm\Finall_Project\venv\lib\site-packages\flask\app.py", line 880, in full_dispatch_request
    rv = self.dispatch_request()
  File "C:\pycharm\Finall_Project\venv\lib\site-packages\flask\app.py", line 865, in dispatch_request
    return self.ensure_sync(self.view_functions[rule.endpoint])(**view_args)  # type: ignore[no-any-return]
  File "C:\pycharm\Finall_Project\venv\lib\site-packages\flask_login\utils.py", line 290, in decorated_view
    return current_app.ensure_sync(func)(*args, **kwargs)
  File "C:\pycharm\Finall_Project\app\routes.py", line 209, in chats
    return render_template('chats.html', chats=user_chats)
  File "C:\pycharm\Finall_Project\venv\lib\site-packages\flask\templating.py", line 150, in render_template
    return _render(app, template, context)
  File "C:\pycharm\Finall_Project\venv\lib\site-packages\flask\templating.py", line 131, in _render
    rv = template.render(context)
  File "C:\pycharm\Finall_Project\venv\lib\site-packages\jinja2\environment.py", line 1304, in render
    self.environment.handle_exception()
  File "C:\pycharm\Finall_Project\venv\lib\site-packages\jinja2\environment.py", line 939, in handle_exception
    raise rewrite_traceback_stack(source=source)
  File "C:\pycharm\Finall_Project\app\templates\chats.html", line 1, in top-level template code
    {% extends "base.html" %}
  File "C:\pycharm\Finall_Project\app\templates\base.html", line 34, in top-level template code
    {% block content %}{% endblock %}
  File "C:\pycharm\Finall_Project\app\templates\chats.html", line 10, in block 'content'
    Chat with {{ other_user.username }}
  File "C:\pycharm\Finall_Project\venv\lib\site-packages\jinja2\environment.py", line 487, in getattr
    return getattr(obj, attribute)
jinja2.exceptions.UndefinedError: 'app.models.Chat object' has no attribute 'user2'
2024-11-06 13:43:38,842 INFO: Blog startup [in C:\pycharm\Finall_Project\app\__init__.py:31]
2024-11-06 13:50:15,615 INFO: Blog startup [in C:\pycharm\Finall_Project\app\__init__.py:31]
2024-11-06 13:53:47,410 INFO: Blog startup [in C:\pycharm\Finall_Project\app\__init__.py:31]
2024-11-06 14:00:49,873 INFO: Blog startup [in C:\pycharm\Finall_Project\app\__init__.py:31]
2024-11-06 14:01:34,837 INFO: Blog startup [in C:\pycharm\Finall_Project\app\__init__.py:31]
2024-11-06 14:02:33,086 INFO: Blog startup [in C:\pycharm\Finall_Project\app\__init__.py:31]
2024-11-06 14:15:01,632 INFO: Blog startup [in C:\pycharm\Finall_Project\app\__init__.py:31]
2024-11-06 14:15:33,426 ERROR: Exception on /chat/3 [GET] [in C:\pycharm\Finall_Project\venv\lib\site-packages\flask\app.py:838]
Traceback (most recent call last):
  File "C:\pycharm\Finall_Project\venv\lib\site-packages\flask\app.py", line 1473, in wsgi_app
    response = self.full_dispatch_request()
  File "C:\pycharm\Finall_Project\venv\lib\site-packages\flask\app.py", line 883, in full_dispatch_request
    return self.finalize_request(rv)
  File "C:\pycharm\Finall_Project\venv\lib\site-packages\flask\app.py", line 902, in finalize_request
    response = self.make_response(rv)
  File "C:\pycharm\Finall_Project\venv\lib\site-packages\flask\app.py", line 1174, in make_response
    raise TypeError(
TypeError: The view function for 'chat' did not return a valid response. The function either returned None or ended without a return statement.
2024-11-06 14:20:25,400 INFO: Blog startup [in C:\pycharm\Finall_Project\app\__init__.py:31]
2024-11-06 14:21:00,106 ERROR: Exception on /chat/1 [GET] [in C:\pycharm\Finall_Project\venv\lib\site-packages\flask\app.py:838]
Traceback (most recent call last):
  File "C:\pycharm\Finall_Project\venv\lib\site-packages\flask\app.py", line 1473, in wsgi_app
    response = self.full_dispatch_request()
  File "C:\pycharm\Finall_Project\venv\lib\site-packages\flask\app.py", line 883, in full_dispatch_request
    return self.finalize_request(rv)
  File "C:\pycharm\Finall_Project\venv\lib\site-packages\flask\app.py", line 902, in finalize_request
    response = self.make_response(rv)
  File "C:\pycharm\Finall_Project\venv\lib\site-packages\flask\app.py", line 1174, in make_response
    raise TypeError(
TypeError: The view function for 'chat' did not return a valid response. The function either returned None or ended without a return statement.
2024-11-06 14:21:00,523 ERROR: Exception on /chat/1 [GET] [in C:\pycharm\Finall_Project\venv\lib\site-packages\flask\app.py:838]
Traceback (most recent call last):
  File "C:\pycharm\Finall_Project\venv\lib\site-packages\flask\app.py", line 1473, in wsgi_app
    response = self.full_dispatch_request()
  File "C:\pycharm\Finall_Project\venv\lib\site-packages\flask\app.py", line 883, in full_dispatch_request
    return self.finalize_request(rv)
  File "C:\pycharm\Finall_Project\venv\lib\site-packages\flask\app.py", line 902, in finalize_request
    response = self.make_response(rv)
  File "C:\pycharm\Finall_Project\venv\lib\site-packages\flask\app.py", line 1174, in make_response
    raise TypeError(
TypeError: The view function for 'chat' did not return a valid response. The function either returned None or ended without a return statement.
2024-11-06 14:21:08,919 ERROR: Exception on /chat/4 [GET] [in C:\pycharm\Finall_Project\venv\lib\site-packages\flask\app.py:838]
Traceback (most recent call last):
  File "C:\pycharm\Finall_Project\venv\lib\site-packages\flask\app.py", line 1473, in wsgi_app
    response = self.full_dispatch_request()
  File "C:\pycharm\Finall_Project\venv\lib\site-packages\flask\app.py", line 883, in full_dispatch_request
    return self.finalize_request(rv)
  File "C:\pycharm\Finall_Project\venv\lib\site-packages\flask\app.py", line 902, in finalize_request
    response = self.make_response(rv)
  File "C:\pycharm\Finall_Project\venv\lib\site-packages\flask\app.py", line 1174, in make_response
    raise TypeError(
TypeError: The view function for 'chat' did not return a valid response. The function either returned None or ended without a return statement.
2024-11-06 14:25:08,021 INFO: Blog startup [in C:\pycharm\Finall_Project\app\__init__.py:31]
2024-11-06 14:35:32,953 INFO: Blog startup [in C:\pycharm\Finall_Project\app\__init__.py:31]
2024-11-06 14:37:07,362 INFO: Blog startup [in C:\pycharm\Finall_Project\app\__init__.py:31]
2024-11-06 14:39:23,422 INFO: Blog startup [in C:\pycharm\Finall_Project\app\__init__.py:31]
2024-11-06 14:41:33,236 INFO: Blog startup [in C:\pycharm\Finall_Project\app\__init__.py:31]
2024-11-06 14:42:25,668 INFO: Blog startup [in C:\pycharm\Finall_Project\app\__init__.py:31]
2024-11-06 14:43:22,107 INFO: Blog startup [in C:\pycharm\Finall_Project\app\__init__.py:31]
2024-11-06 14:48:46,929 INFO: Blog startup [in C:\pycharm\Finall_Project\app\__init__.py:31]
2024-11-06 14:48:49,986 INFO: Blog startup [in C:\pycharm\Finall_Project\app\__init__.py:31]
2024-11-06 14:53:51,013 INFO: Blog startup [in C:\pycharm\Finall_Project\app\__init__.py:31]
2024-11-06 14:57:02,264 INFO: Blog startup [in C:\pycharm\Finall_Project\app\__init__.py:31]
