2024-11-14 18:43:52,610 ERROR: Exception on /user/john [GET] [in C:\pycharm\Finall_Project\venv\lib\site-packages\flask\app.py:838]
Traceback (most recent call last):
  File "C:\pycharm\Finall_Project\venv\lib\site-packages\flask\app.py", line 1473, in wsgi_app
    response = self.full_dispatch_request()
  File "C:\pycharm\Finall_Project\venv\lib\site-packages\flask\app.py", line 882, in full_dispatch_request
    rv = self.handle_user_exception(e)
  File "C:\pycharm\Finall_Project\venv\lib\site-packages\flask\app.py", line 880, in full_dispatch_request
    rv = self.dispatch_request()
  File "C:\pycharm\Finall_Project\venv\lib\site-packages\flask\app.py", line 865, in dispatch_request
    return self.ensure_sync(self.view_functions[rule.endpoint])(**view_args)  # type: ignore[no-any-return]
  File "C:\pycharm\Finall_Project\venv\lib\site-packages\flask_login\utils.py", line 290, in decorated_view
    return current_app.ensure_sync(func)(*args, **kwargs)
  File "C:\pycharm\Finall_Project\app\routes.py", line 110, in user
    return render_template('user.html', user=user, posts=posts.items,
  File "C:\pycharm\Finall_Project\venv\lib\site-packages\flask\templating.py", line 150, in render_template
    return _render(app, template, context)
  File "C:\pycharm\Finall_Project\venv\lib\site-packages\flask\templating.py", line 131, in _render
    rv = template.render(context)
  File "C:\pycharm\Finall_Project\venv\lib\site-packages\jinja2\environment.py", line 1304, in render
    self.environment.handle_exception()
  File "C:\pycharm\Finall_Project\venv\lib\site-packages\jinja2\environment.py", line 939, in handle_exception
    raise rewrite_traceback_stack(source=source)
  File "C:\pycharm\Finall_Project\app\templates\user.html", line 1, in top-level template code
    {% extends "base.html" %}
  File "C:\pycharm\Finall_Project\app\templates\base.html", line 40, in top-level template code
    {% block content %}{% endblock %}
  File "C:\pycharm\Finall_Project\app\templates\user.html", line 35, in block 'content'
    {% if current_user.is_authenticated and current_user.has_unread_messages() %}
  File "C:\pycharm\Finall_Project\app\models.py", line 55, in has_unread_messages
    return any(chat.unread_count > 0 for chat in self.chats)
AttributeError: 'User' object has no attribute 'chats'
2024-11-14 18:44:04,517 ERROR: Exception on /user/john [GET] [in C:\pycharm\Finall_Project\venv\lib\site-packages\flask\app.py:838]
Traceback (most recent call last):
  File "C:\pycharm\Finall_Project\venv\lib\site-packages\flask\app.py", line 1473, in wsgi_app
    response = self.full_dispatch_request()
  File "C:\pycharm\Finall_Project\venv\lib\site-packages\flask\app.py", line 882, in full_dispatch_request
    rv = self.handle_user_exception(e)
  File "C:\pycharm\Finall_Project\venv\lib\site-packages\flask\app.py", line 880, in full_dispatch_request
    rv = self.dispatch_request()
  File "C:\pycharm\Finall_Project\venv\lib\site-packages\flask\app.py", line 865, in dispatch_request
    return self.ensure_sync(self.view_functions[rule.endpoint])(**view_args)  # type: ignore[no-any-return]
  File "C:\pycharm\Finall_Project\venv\lib\site-packages\flask_login\utils.py", line 290, in decorated_view
    return current_app.ensure_sync(func)(*args, **kwargs)
  File "C:\pycharm\Finall_Project\app\routes.py", line 110, in user
    return render_template('user.html', user=user, posts=posts.items,
  File "C:\pycharm\Finall_Project\venv\lib\site-packages\flask\templating.py", line 150, in render_template
    return _render(app, template, context)
  File "C:\pycharm\Finall_Project\venv\lib\site-packages\flask\templating.py", line 131, in _render
    rv = template.render(context)
  File "C:\pycharm\Finall_Project\venv\lib\site-packages\jinja2\environment.py", line 1304, in render
    self.environment.handle_exception()
  File "C:\pycharm\Finall_Project\venv\lib\site-packages\jinja2\environment.py", line 939, in handle_exception
    raise rewrite_traceback_stack(source=source)
  File "C:\pycharm\Finall_Project\app\templates\user.html", line 1, in top-level template code
    {% extends "base.html" %}
  File "C:\pycharm\Finall_Project\app\templates\base.html", line 40, in top-level template code
    {% block content %}{% endblock %}
  File "C:\pycharm\Finall_Project\app\templates\user.html", line 35, in block 'content'
    {% if current_user.is_authenticated and current_user.has_unread_messages() %}
  File "C:\pycharm\Finall_Project\app\models.py", line 55, in has_unread_messages
    return any(chat.unread_count > 0 for chat in self.chats)
AttributeError: 'User' object has no attribute 'chats'
2024-11-14 18:44:29,404 INFO: Blog startup [in C:\pycharm\Finall_Project\app\__init__.py:31]
2024-11-14 18:44:32,133 ERROR: Exception on /user/john [GET] [in C:\pycharm\Finall_Project\venv\lib\site-packages\flask\app.py:838]
Traceback (most recent call last):
  File "C:\pycharm\Finall_Project\venv\lib\site-packages\flask\app.py", line 1473, in wsgi_app
    response = self.full_dispatch_request()
  File "C:\pycharm\Finall_Project\venv\lib\site-packages\flask\app.py", line 882, in full_dispatch_request
    rv = self.handle_user_exception(e)
  File "C:\pycharm\Finall_Project\venv\lib\site-packages\flask\app.py", line 880, in full_dispatch_request
    rv = self.dispatch_request()
  File "C:\pycharm\Finall_Project\venv\lib\site-packages\flask\app.py", line 865, in dispatch_request
    return self.ensure_sync(self.view_functions[rule.endpoint])(**view_args)  # type: ignore[no-any-return]
  File "C:\pycharm\Finall_Project\venv\lib\site-packages\flask_login\utils.py", line 290, in decorated_view
    return current_app.ensure_sync(func)(*args, **kwargs)
  File "C:\pycharm\Finall_Project\app\routes.py", line 110, in user
    return render_template('user.html', user=user, posts=posts.items,
  File "C:\pycharm\Finall_Project\venv\lib\site-packages\flask\templating.py", line 150, in render_template
    return _render(app, template, context)
  File "C:\pycharm\Finall_Project\venv\lib\site-packages\flask\templating.py", line 131, in _render
    rv = template.render(context)
  File "C:\pycharm\Finall_Project\venv\lib\site-packages\jinja2\environment.py", line 1304, in render
    self.environment.handle_exception()
  File "C:\pycharm\Finall_Project\venv\lib\site-packages\jinja2\environment.py", line 939, in handle_exception
    raise rewrite_traceback_stack(source=source)
  File "C:\pycharm\Finall_Project\app\templates\user.html", line 1, in top-level template code
    {% extends "base.html" %}
  File "C:\pycharm\Finall_Project\app\templates\base.html", line 40, in top-level template code
    {% block content %}{% endblock %}
  File "C:\pycharm\Finall_Project\app\templates\user.html", line 35, in block 'content'
    {% if current_user.is_authenticated and current_user.has_unread_messages() %}
  File "C:\pycharm\Finall_Project\app\models.py", line 55, in has_unread_messages
    return any(chat.unread_count > 0 for chat in self.chats)
AttributeError: 'User' object has no attribute 'chats'
2024-11-14 18:50:51,638 INFO: Blog startup [in C:\pycharm\Finall_Project\app\__init__.py:31]
2024-11-14 18:50:58,527 INFO: Blog startup [in C:\pycharm\Finall_Project\app\__init__.py:31]
2024-11-14 18:51:06,852 INFO: Blog startup [in C:\pycharm\Finall_Project\app\__init__.py:31]
